2024-08-26 02:30:24,365 ERROR: Exception on / [GET] [in /home/abraham-forkuo/Documents/EYP-EPMS/venv/lib/python3.12/site-packages/flask/app.py:838]
Traceback (most recent call last):
  File "/home/abraham-forkuo/Documents/EYP-EPMS/venv/lib/python3.12/site-packages/flask/app.py", line 1473, in wsgi_app
    response = self.full_dispatch_request()
               ^^^^^^^^^^^^^^^^^^^^^^^^^^^^
  File "/home/abraham-forkuo/Documents/EYP-EPMS/venv/lib/python3.12/site-packages/flask/app.py", line 882, in full_dispatch_request
    rv = self.handle_user_exception(e)
         ^^^^^^^^^^^^^^^^^^^^^^^^^^^^^
  File "/home/abraham-forkuo/Documents/EYP-EPMS/venv/lib/python3.12/site-packages/flask/app.py", line 880, in full_dispatch_request
    rv = self.dispatch_request()
         ^^^^^^^^^^^^^^^^^^^^^^^
  File "/home/abraham-forkuo/Documents/EYP-EPMS/venv/lib/python3.12/site-packages/flask/app.py", line 865, in dispatch_request
    return self.ensure_sync(self.view_functions[rule.endpoint])(**view_args)  # type: ignore[no-any-return]
           ^^^^^^^^^^^^^^^^^^^^^^^^^^^^^^^^^^^^^^^^^^^^^^^^^^^^^^^^^^^^^^^^^
  File "/home/abraham-forkuo/Documents/EYP-EPMS/epms/app/routes/auth.py", line 12, in login
    if current_user.is_authenticated:
       ^^^^^^^^^^^^^^^^^^^^^^^^^^^^^
  File "/home/abraham-forkuo/Documents/EYP-EPMS/venv/lib/python3.12/site-packages/werkzeug/local.py", line 318, in __get__
    obj = instance._get_current_object()
          ^^^^^^^^^^^^^^^^^^^^^^^^^^^^^^
  File "/home/abraham-forkuo/Documents/EYP-EPMS/venv/lib/python3.12/site-packages/werkzeug/local.py", line 526, in _get_current_object
    return get_name(local())
                    ^^^^^^^
  File "/home/abraham-forkuo/Documents/EYP-EPMS/venv/lib/python3.12/site-packages/flask_login/utils.py", line 25, in <lambda>
    current_user = LocalProxy(lambda: _get_user())
                                      ^^^^^^^^^^^
  File "/home/abraham-forkuo/Documents/EYP-EPMS/venv/lib/python3.12/site-packages/flask_login/utils.py", line 370, in _get_user
    current_app.login_manager._load_user()
  File "/home/abraham-forkuo/Documents/EYP-EPMS/venv/lib/python3.12/site-packages/flask_login/login_manager.py", line 364, in _load_user
    user = self._user_callback(user_id)
           ^^^^^^^^^^^^^^^^^^^^^^^^^^^^
  File "/home/abraham-forkuo/Documents/EYP-EPMS/epms/app/models/user.py", line 6, in load_user
    return User.query.get(int(user_id))
           ^^^^^^^^^^
  File "/home/abraham-forkuo/Documents/EYP-EPMS/venv/lib/python3.12/site-packages/flask_sqlalchemy/model.py", line 22, in __get__
    return cls.query_class(
           ^^^^^^^^^^^^^^^^
  File "/home/abraham-forkuo/Documents/EYP-EPMS/venv/lib/python3.12/site-packages/sqlalchemy/orm/query.py", line 275, in __init__
    self._set_entities(entities)
  File "/home/abraham-forkuo/Documents/EYP-EPMS/venv/lib/python3.12/site-packages/sqlalchemy/orm/query.py", line 288, in _set_entities
    coercions.expect(
  File "/home/abraham-forkuo/Documents/EYP-EPMS/venv/lib/python3.12/site-packages/sqlalchemy/sql/coercions.py", line 389, in expect
    insp._post_inspect
  File "/home/abraham-forkuo/Documents/EYP-EPMS/venv/lib/python3.12/site-packages/sqlalchemy/util/langhelpers.py", line 1253, in __get__
    obj.__dict__[self.__name__] = result = self.fget(obj)
                                           ^^^^^^^^^^^^^^
  File "/home/abraham-forkuo/Documents/EYP-EPMS/venv/lib/python3.12/site-packages/sqlalchemy/orm/mapper.py", line 2711, in _post_inspect
    self._check_configure()
  File "/home/abraham-forkuo/Documents/EYP-EPMS/venv/lib/python3.12/site-packages/sqlalchemy/orm/mapper.py", line 2388, in _check_configure
    _configure_registries({self.registry}, cascade=True)
  File "/home/abraham-forkuo/Documents/EYP-EPMS/venv/lib/python3.12/site-packages/sqlalchemy/orm/mapper.py", line 4204, in _configure_registries
    _do_configure_registries(registries, cascade)
  File "/home/abraham-forkuo/Documents/EYP-EPMS/venv/lib/python3.12/site-packages/sqlalchemy/orm/mapper.py", line 4241, in _do_configure_registries
    raise e
sqlalchemy.exc.InvalidRequestError: One or more mappers failed to initialize - can't proceed with initialization of other mappers. Triggering mapper: 'Mapper[Schedule(schedule)]'. Original exception was: Could not initialize target column for ForeignKey 'user.id' on table 'schedule': table 'user' has no column named 'id'
2024-08-26 02:30:33,912 INFO: Application startup [in /home/abraham-forkuo/Documents/EYP-EPMS/epms/app/__init__.py:33]
