2024-08-31 02:50:15,944 ERROR: Exception on / [GET] [in /home/abraham-forkuo/Documents/EYP-EPMS/venv/lib/python3.12/site-packages/flask/app.py:838]
Traceback (most recent call last):
  File "/home/abraham-forkuo/Documents/EYP-EPMS/venv/lib/python3.12/site-packages/flask/app.py", line 1473, in wsgi_app
    response = self.full_dispatch_request()
               ^^^^^^^^^^^^^^^^^^^^^^^^^^^^
  File "/home/abraham-forkuo/Documents/EYP-EPMS/venv/lib/python3.12/site-packages/flask/app.py", line 882, in full_dispatch_request
    rv = self.handle_user_exception(e)
         ^^^^^^^^^^^^^^^^^^^^^^^^^^^^^
  File "/home/abraham-forkuo/Documents/EYP-EPMS/venv/lib/python3.12/site-packages/flask/app.py", line 880, in full_dispatch_request
    rv = self.dispatch_request()
         ^^^^^^^^^^^^^^^^^^^^^^^
  File "/home/abraham-forkuo/Documents/EYP-EPMS/venv/lib/python3.12/site-packages/flask/app.py", line 865, in dispatch_request
    return self.ensure_sync(self.view_functions[rule.endpoint])(**view_args)  # type: ignore[no-any-return]
           ^^^^^^^^^^^^^^^^^^^^^^^^^^^^^^^^^^^^^^^^^^^^^^^^^^^^^^^^^^^^^^^^^
  File "/home/abraham-forkuo/Documents/EYP-EPMS/epms/app/routes/auth.py", line 36, in login
    return render_template('login.html', form=form)
           ^^^^^^^^^^^^^^^^^^^^^^^^^^^^^^^^^^^^^^^^
  File "/home/abraham-forkuo/Documents/EYP-EPMS/venv/lib/python3.12/site-packages/flask/templating.py", line 150, in render_template
    return _render(app, template, context)
           ^^^^^^^^^^^^^^^^^^^^^^^^^^^^^^^
  File "/home/abraham-forkuo/Documents/EYP-EPMS/venv/lib/python3.12/site-packages/flask/templating.py", line 131, in _render
    rv = template.render(context)
         ^^^^^^^^^^^^^^^^^^^^^^^^
  File "/home/abraham-forkuo/Documents/EYP-EPMS/venv/lib/python3.12/site-packages/jinja2/environment.py", line 1304, in render
    self.environment.handle_exception()
  File "/home/abraham-forkuo/Documents/EYP-EPMS/venv/lib/python3.12/site-packages/jinja2/environment.py", line 939, in handle_exception
    raise rewrite_traceback_stack(source=source)
  File "/home/abraham-forkuo/Documents/EYP-EPMS/epms/app/templates/login.html", line 32, in top-level template code
    <p><a href="{{ url_for('auth.reset_password') }}">Forgot Password?</a></p>
    ^^^^^^^^^^^^^^^^^^^^^^^^^
  File "/home/abraham-forkuo/Documents/EYP-EPMS/venv/lib/python3.12/site-packages/flask/app.py", line 1084, in url_for
    return self.handle_url_build_error(error, endpoint, values)
           ^^^^^^^^^^^^^^^^^^^^^^^^^^^^^^^^^^^^^^^^^^^^^^^^^^^^
  File "/home/abraham-forkuo/Documents/EYP-EPMS/venv/lib/python3.12/site-packages/flask/app.py", line 1073, in url_for
    rv = url_adapter.build(  # type: ignore[union-attr]
         ^^^^^^^^^^^^^^^^^^^^^^^^^^^^^^^^^^^^^^^^^^^^^^
  File "/home/abraham-forkuo/Documents/EYP-EPMS/venv/lib/python3.12/site-packages/werkzeug/routing/map.py", line 924, in build
    raise BuildError(endpoint, values, method, self)
werkzeug.routing.exceptions.BuildError: Could not build url for endpoint 'auth.reset_password'. Did you forget to specify values ['token']?
2024-08-31 02:50:46,372 INFO: Application startup [in /home/abraham-forkuo/Documents/EYP-EPMS/epms/app/__init__.py:40]
2024-08-31 02:51:11,880 ERROR: Exception on /forgot_password [POST] [in /home/abraham-forkuo/Documents/EYP-EPMS/venv/lib/python3.12/site-packages/flask/app.py:838]
Traceback (most recent call last):
  File "/home/abraham-forkuo/Documents/EYP-EPMS/venv/lib/python3.12/site-packages/flask/app.py", line 1473, in wsgi_app
    response = self.full_dispatch_request()
               ^^^^^^^^^^^^^^^^^^^^^^^^^^^^
  File "/home/abraham-forkuo/Documents/EYP-EPMS/venv/lib/python3.12/site-packages/flask/app.py", line 882, in full_dispatch_request
    rv = self.handle_user_exception(e)
         ^^^^^^^^^^^^^^^^^^^^^^^^^^^^^
  File "/home/abraham-forkuo/Documents/EYP-EPMS/venv/lib/python3.12/site-packages/flask/app.py", line 880, in full_dispatch_request
    rv = self.dispatch_request()
         ^^^^^^^^^^^^^^^^^^^^^^^
  File "/home/abraham-forkuo/Documents/EYP-EPMS/venv/lib/python3.12/site-packages/flask/app.py", line 865, in dispatch_request
    return self.ensure_sync(self.view_functions[rule.endpoint])(**view_args)  # type: ignore[no-any-return]
           ^^^^^^^^^^^^^^^^^^^^^^^^^^^^^^^^^^^^^^^^^^^^^^^^^^^^^^^^^^^^^^^^^
  File "/home/abraham-forkuo/Documents/EYP-EPMS/epms/app/routes/auth.py", line 54, in forgot_password
    send_reset_email(user)
  File "/home/abraham-forkuo/Documents/EYP-EPMS/epms/app/utils/mail.py", line 7, in send_reset_email
    token = user.get_reset_token()
            ^^^^^^^^^^^^^^^^^^^^^^
  File "/home/abraham-forkuo/Documents/EYP-EPMS/epms/app/models/user.py", line 28, in get_reset_token
    return s.dumps({'user_id': self.id}).decode('utf-8')
                               ^^^^^^^
AttributeError: 'User' object has no attribute 'id'
2024-08-31 02:52:49,316 INFO: Application startup [in /home/abraham-forkuo/Documents/EYP-EPMS/epms/app/__init__.py:40]
2024-08-31 02:52:56,710 ERROR: Exception on /forgot_password [POST] [in /home/abraham-forkuo/Documents/EYP-EPMS/venv/lib/python3.12/site-packages/flask/app.py:838]
Traceback (most recent call last):
  File "/home/abraham-forkuo/Documents/EYP-EPMS/venv/lib/python3.12/site-packages/flask/app.py", line 1473, in wsgi_app
    response = self.full_dispatch_request()
               ^^^^^^^^^^^^^^^^^^^^^^^^^^^^
  File "/home/abraham-forkuo/Documents/EYP-EPMS/venv/lib/python3.12/site-packages/flask/app.py", line 882, in full_dispatch_request
    rv = self.handle_user_exception(e)
         ^^^^^^^^^^^^^^^^^^^^^^^^^^^^^
  File "/home/abraham-forkuo/Documents/EYP-EPMS/venv/lib/python3.12/site-packages/flask/app.py", line 880, in full_dispatch_request
    rv = self.dispatch_request()
         ^^^^^^^^^^^^^^^^^^^^^^^
  File "/home/abraham-forkuo/Documents/EYP-EPMS/venv/lib/python3.12/site-packages/flask/app.py", line 865, in dispatch_request
    return self.ensure_sync(self.view_functions[rule.endpoint])(**view_args)  # type: ignore[no-any-return]
           ^^^^^^^^^^^^^^^^^^^^^^^^^^^^^^^^^^^^^^^^^^^^^^^^^^^^^^^^^^^^^^^^^
  File "/home/abraham-forkuo/Documents/EYP-EPMS/epms/app/routes/auth.py", line 54, in forgot_password
    send_reset_email(user)
  File "/home/abraham-forkuo/Documents/EYP-EPMS/epms/app/utils/mail.py", line 7, in send_reset_email
    token = user.get_reset_token()
            ^^^^^^^^^^^^^^^^^^^^^^
  File "/home/abraham-forkuo/Documents/EYP-EPMS/epms/app/models/user.py", line 28, in get_reset_token
    return s.dumps({'user_id': self.user_id}).decode('utf-8')
           ^^^^^^^^^^^^^^^^^^^^^^^^^^^^^^^^^^
  File "/home/abraham-forkuo/Documents/EYP-EPMS/venv/lib/python3.12/site-packages/itsdangerous/serializer.py", line 317, in dumps
    rv = self.make_signer(salt).sign(payload)
         ^^^^^^^^^^^^^^^^^^^^^^^^^^^^^^^^^^^^
  File "/home/abraham-forkuo/Documents/EYP-EPMS/venv/lib/python3.12/site-packages/itsdangerous/timed.py", line 51, in sign
    return value + sep + self.get_signature(value)
                         ^^^^^^^^^^^^^^^^^^^^^^^^^
  File "/home/abraham-forkuo/Documents/EYP-EPMS/venv/lib/python3.12/site-packages/itsdangerous/signer.py", line 218, in get_signature
    key = self.derive_key()
          ^^^^^^^^^^^^^^^^^
  File "/home/abraham-forkuo/Documents/EYP-EPMS/venv/lib/python3.12/site-packages/itsdangerous/signer.py", line 204, in derive_key
    bytes, self.digest_method(self.salt + b"signer" + secret_key).digest()
                              ~~~~~~~~~~^~~~~~~~~~~
TypeError: unsupported operand type(s) for +: 'int' and 'bytes'
2024-08-31 02:53:56,965 INFO: Application startup [in /home/abraham-forkuo/Documents/EYP-EPMS/epms/app/__init__.py:40]
2024-08-31 02:54:06,308 ERROR: Exception on /forgot_password [POST] [in /home/abraham-forkuo/Documents/EYP-EPMS/venv/lib/python3.12/site-packages/flask/app.py:838]
Traceback (most recent call last):
  File "/home/abraham-forkuo/Documents/EYP-EPMS/venv/lib/python3.12/site-packages/flask/app.py", line 1473, in wsgi_app
    response = self.full_dispatch_request()
               ^^^^^^^^^^^^^^^^^^^^^^^^^^^^
  File "/home/abraham-forkuo/Documents/EYP-EPMS/venv/lib/python3.12/site-packages/flask/app.py", line 882, in full_dispatch_request
    rv = self.handle_user_exception(e)
         ^^^^^^^^^^^^^^^^^^^^^^^^^^^^^
  File "/home/abraham-forkuo/Documents/EYP-EPMS/venv/lib/python3.12/site-packages/flask/app.py", line 880, in full_dispatch_request
    rv = self.dispatch_request()
         ^^^^^^^^^^^^^^^^^^^^^^^
  File "/home/abraham-forkuo/Documents/EYP-EPMS/venv/lib/python3.12/site-packages/flask/app.py", line 865, in dispatch_request
    return self.ensure_sync(self.view_functions[rule.endpoint])(**view_args)  # type: ignore[no-any-return]
           ^^^^^^^^^^^^^^^^^^^^^^^^^^^^^^^^^^^^^^^^^^^^^^^^^^^^^^^^^^^^^^^^^
  File "/home/abraham-forkuo/Documents/EYP-EPMS/epms/app/routes/auth.py", line 54, in forgot_password
    send_reset_email(user)
  File "/home/abraham-forkuo/Documents/EYP-EPMS/epms/app/utils/mail.py", line 7, in send_reset_email
    token = user.get_reset_token()
            ^^^^^^^^^^^^^^^^^^^^
AttributeError: 'User' object has no attribute 'get_reset_token'. Did you mean: 'reset_token'?
2024-08-31 02:55:55,006 INFO: Application startup [in /home/abraham-forkuo/Documents/EYP-EPMS/epms/app/__init__.py:40]
