2024-09-25 07:43:32,424 ERROR: Exception on /admin/delete_user/6 [POST] [in /home/abraham-forkuo/Documents/EYP-EPMS/venv/lib/python3.12/site-packages/flask/app.py:838]
Traceback (most recent call last):
  File "/home/abraham-forkuo/Documents/EYP-EPMS/venv/lib/python3.12/site-packages/sqlalchemy/engine/base.py", line 1967, in _exec_single_context
    self.dialect.do_execute(
  File "/home/abraham-forkuo/Documents/EYP-EPMS/venv/lib/python3.12/site-packages/sqlalchemy/engine/default.py", line 924, in do_execute
    cursor.execute(statement, parameters)
  File "/home/abraham-forkuo/Documents/EYP-EPMS/venv/lib/python3.12/site-packages/pymysql/cursors.py", line 153, in execute
    result = self._query(query)
             ^^^^^^^^^^^^^^^^^^
  File "/home/abraham-forkuo/Documents/EYP-EPMS/venv/lib/python3.12/site-packages/pymysql/cursors.py", line 322, in _query
    conn.query(q)
  File "/home/abraham-forkuo/Documents/EYP-EPMS/venv/lib/python3.12/site-packages/pymysql/connections.py", line 563, in query
    self._affected_rows = self._read_query_result(unbuffered=unbuffered)
                          ^^^^^^^^^^^^^^^^^^^^^^^^^^^^^^^^^^^^^^^^^^^^^^
  File "/home/abraham-forkuo/Documents/EYP-EPMS/venv/lib/python3.12/site-packages/pymysql/connections.py", line 825, in _read_query_result
    result.read()
  File "/home/abraham-forkuo/Documents/EYP-EPMS/venv/lib/python3.12/site-packages/pymysql/connections.py", line 1199, in read
    first_packet = self.connection._read_packet()
                   ^^^^^^^^^^^^^^^^^^^^^^^^^^^^^^
  File "/home/abraham-forkuo/Documents/EYP-EPMS/venv/lib/python3.12/site-packages/pymysql/connections.py", line 775, in _read_packet
    packet.raise_for_error()
  File "/home/abraham-forkuo/Documents/EYP-EPMS/venv/lib/python3.12/site-packages/pymysql/protocol.py", line 219, in raise_for_error
    err.raise_mysql_exception(self._data)
  File "/home/abraham-forkuo/Documents/EYP-EPMS/venv/lib/python3.12/site-packages/pymysql/err.py", line 150, in raise_mysql_exception
    raise errorclass(errno, errval)
pymysql.err.IntegrityError: (1451, 'Cannot delete or update a parent row: a foreign key constraint fails (`epms_db`.`schedules`, CONSTRAINT `schedules_ibfk_1` FOREIGN KEY (`examiner_id`) REFERENCES `user` (`user_id`))')

The above exception was the direct cause of the following exception:

Traceback (most recent call last):
  File "/home/abraham-forkuo/Documents/EYP-EPMS/venv/lib/python3.12/site-packages/flask/app.py", line 1473, in wsgi_app
    response = self.full_dispatch_request()
               ^^^^^^^^^^^^^^^^^^^^^^^^^^^^
  File "/home/abraham-forkuo/Documents/EYP-EPMS/venv/lib/python3.12/site-packages/flask/app.py", line 882, in full_dispatch_request
    rv = self.handle_user_exception(e)
         ^^^^^^^^^^^^^^^^^^^^^^^^^^^^^
  File "/home/abraham-forkuo/Documents/EYP-EPMS/venv/lib/python3.12/site-packages/flask/app.py", line 880, in full_dispatch_request
    rv = self.dispatch_request()
         ^^^^^^^^^^^^^^^^^^^^^^^
  File "/home/abraham-forkuo/Documents/EYP-EPMS/venv/lib/python3.12/site-packages/flask/app.py", line 865, in dispatch_request
    return self.ensure_sync(self.view_functions[rule.endpoint])(**view_args)  # type: ignore[no-any-return]
           ^^^^^^^^^^^^^^^^^^^^^^^^^^^^^^^^^^^^^^^^^^^^^^^^^^^^^^^^^^^^^^^^^
  File "/home/abraham-forkuo/Documents/EYP-EPMS/venv/lib/python3.12/site-packages/flask_login/utils.py", line 290, in decorated_view
    return current_app.ensure_sync(func)(*args, **kwargs)
           ^^^^^^^^^^^^^^^^^^^^^^^^^^^^^^^^^^^^^^^^^^^^^^
  File "/home/abraham-forkuo/Documents/EYP-EPMS/epms/app/routes/admin.py", line 20, in decorated_view
    return f(*args, **kwargs)
           ^^^^^^^^^^^^^^^^^^
  File "/home/abraham-forkuo/Documents/EYP-EPMS/epms/app/routes/admin.py", line 145, in delete_user
    db.session.commit()
  File "/home/abraham-forkuo/Documents/EYP-EPMS/venv/lib/python3.12/site-packages/sqlalchemy/orm/scoping.py", line 597, in commit
    return self._proxied.commit()
           ^^^^^^^^^^^^^^^^^^^^^^
  File "/home/abraham-forkuo/Documents/EYP-EPMS/venv/lib/python3.12/site-packages/sqlalchemy/orm/session.py", line 2017, in commit
    trans.commit(_to_root=True)
  File "<string>", line 2, in commit
  File "/home/abraham-forkuo/Documents/EYP-EPMS/venv/lib/python3.12/site-packages/sqlalchemy/orm/state_changes.py", line 139, in _go
    ret_value = fn(self, *arg, **kw)
                ^^^^^^^^^^^^^^^^^^^^
  File "/home/abraham-forkuo/Documents/EYP-EPMS/venv/lib/python3.12/site-packages/sqlalchemy/orm/session.py", line 1302, in commit
    self._prepare_impl()
  File "<string>", line 2, in _prepare_impl
  File "/home/abraham-forkuo/Documents/EYP-EPMS/venv/lib/python3.12/site-packages/sqlalchemy/orm/state_changes.py", line 139, in _go
    ret_value = fn(self, *arg, **kw)
                ^^^^^^^^^^^^^^^^^^^^
  File "/home/abraham-forkuo/Documents/EYP-EPMS/venv/lib/python3.12/site-packages/sqlalchemy/orm/session.py", line 1277, in _prepare_impl
    self.session.flush()
  File "/home/abraham-forkuo/Documents/EYP-EPMS/venv/lib/python3.12/site-packages/sqlalchemy/orm/session.py", line 4341, in flush
    self._flush(objects)
  File "/home/abraham-forkuo/Documents/EYP-EPMS/venv/lib/python3.12/site-packages/sqlalchemy/orm/session.py", line 4476, in _flush
    with util.safe_reraise():
  File "/home/abraham-forkuo/Documents/EYP-EPMS/venv/lib/python3.12/site-packages/sqlalchemy/util/langhelpers.py", line 146, in __exit__
    raise exc_value.with_traceback(exc_tb)
  File "/home/abraham-forkuo/Documents/EYP-EPMS/venv/lib/python3.12/site-packages/sqlalchemy/orm/session.py", line 4437, in _flush
    flush_context.execute()
  File "/home/abraham-forkuo/Documents/EYP-EPMS/venv/lib/python3.12/site-packages/sqlalchemy/orm/unitofwork.py", line 466, in execute
    rec.execute(self)
  File "/home/abraham-forkuo/Documents/EYP-EPMS/venv/lib/python3.12/site-packages/sqlalchemy/orm/unitofwork.py", line 679, in execute
    util.preloaded.orm_persistence.delete_obj(
  File "/home/abraham-forkuo/Documents/EYP-EPMS/venv/lib/python3.12/site-packages/sqlalchemy/orm/persistence.py", line 193, in delete_obj
    _emit_delete_statements(
  File "/home/abraham-forkuo/Documents/EYP-EPMS/venv/lib/python3.12/site-packages/sqlalchemy/orm/persistence.py", line 1465, in _emit_delete_statements
    c = connection.execute(
        ^^^^^^^^^^^^^^^^^^^
  File "/home/abraham-forkuo/Documents/EYP-EPMS/venv/lib/python3.12/site-packages/sqlalchemy/engine/base.py", line 1418, in execute
    return meth(
           ^^^^^
  File "/home/abraham-forkuo/Documents/EYP-EPMS/venv/lib/python3.12/site-packages/sqlalchemy/sql/elements.py", line 515, in _execute_on_connection
    return connection._execute_clauseelement(
           ^^^^^^^^^^^^^^^^^^^^^^^^^^^^^^^^^^
  File "/home/abraham-forkuo/Documents/EYP-EPMS/venv/lib/python3.12/site-packages/sqlalchemy/engine/base.py", line 1640, in _execute_clauseelement
    ret = self._execute_context(
          ^^^^^^^^^^^^^^^^^^^^^^
  File "/home/abraham-forkuo/Documents/EYP-EPMS/venv/lib/python3.12/site-packages/sqlalchemy/engine/base.py", line 1846, in _execute_context
    return self._exec_single_context(
           ^^^^^^^^^^^^^^^^^^^^^^^^^^
  File "/home/abraham-forkuo/Documents/EYP-EPMS/venv/lib/python3.12/site-packages/sqlalchemy/engine/base.py", line 1986, in _exec_single_context
    self._handle_dbapi_exception(
  File "/home/abraham-forkuo/Documents/EYP-EPMS/venv/lib/python3.12/site-packages/sqlalchemy/engine/base.py", line 2353, in _handle_dbapi_exception
    raise sqlalchemy_exception.with_traceback(exc_info[2]) from e
  File "/home/abraham-forkuo/Documents/EYP-EPMS/venv/lib/python3.12/site-packages/sqlalchemy/engine/base.py", line 1967, in _exec_single_context
    self.dialect.do_execute(
  File "/home/abraham-forkuo/Documents/EYP-EPMS/venv/lib/python3.12/site-packages/sqlalchemy/engine/default.py", line 924, in do_execute
    cursor.execute(statement, parameters)
  File "/home/abraham-forkuo/Documents/EYP-EPMS/venv/lib/python3.12/site-packages/pymysql/cursors.py", line 153, in execute
    result = self._query(query)
             ^^^^^^^^^^^^^^^^^^
  File "/home/abraham-forkuo/Documents/EYP-EPMS/venv/lib/python3.12/site-packages/pymysql/cursors.py", line 322, in _query
    conn.query(q)
  File "/home/abraham-forkuo/Documents/EYP-EPMS/venv/lib/python3.12/site-packages/pymysql/connections.py", line 563, in query
    self._affected_rows = self._read_query_result(unbuffered=unbuffered)
                          ^^^^^^^^^^^^^^^^^^^^^^^^^^^^^^^^^^^^^^^^^^^^^^
  File "/home/abraham-forkuo/Documents/EYP-EPMS/venv/lib/python3.12/site-packages/pymysql/connections.py", line 825, in _read_query_result
    result.read()
  File "/home/abraham-forkuo/Documents/EYP-EPMS/venv/lib/python3.12/site-packages/pymysql/connections.py", line 1199, in read
    first_packet = self.connection._read_packet()
                   ^^^^^^^^^^^^^^^^^^^^^^^^^^^^^^
  File "/home/abraham-forkuo/Documents/EYP-EPMS/venv/lib/python3.12/site-packages/pymysql/connections.py", line 775, in _read_packet
    packet.raise_for_error()
  File "/home/abraham-forkuo/Documents/EYP-EPMS/venv/lib/python3.12/site-packages/pymysql/protocol.py", line 219, in raise_for_error
    err.raise_mysql_exception(self._data)
  File "/home/abraham-forkuo/Documents/EYP-EPMS/venv/lib/python3.12/site-packages/pymysql/err.py", line 150, in raise_mysql_exception
    raise errorclass(errno, errval)
sqlalchemy.exc.IntegrityError: (pymysql.err.IntegrityError) (1451, 'Cannot delete or update a parent row: a foreign key constraint fails (`epms_db`.`schedules`, CONSTRAINT `schedules_ibfk_1` FOREIGN KEY (`examiner_id`) REFERENCES `user` (`user_id`))')
[SQL: DELETE FROM user WHERE user.user_id = %(user_id)s]
[parameters: {'user_id': 6}]
(Background on this error at: https://sqlalche.me/e/20/gkpj)
2024-09-26 03:19:40,671 INFO: Application startup [in /home/abraham-forkuo/Documents/EYP-EPMS/epms/app/__init__.py:40]
2024-09-26 03:33:05,736 INFO: Application startup [in /home/abraham-forkuo/Documents/EYP-EPMS/epms/app/__init__.py:40]
